Workbook

Sheet CLIENȚI EXISTENȚI
A1: AGRO SALSO — BAZĂ DE DATE CLIENȚI EXISTENȚI
A2: Instrucțiuni: Completează cu TOȚI clienții din agende, facturi, telefon. Începe cu top 20.
A3: Total clienți: | B3: =COUNTA(B5:B204) | D3: Cu potențial upsell: | E3: =COUNTIF(K5:K204,"Da") | G3: Suprafață totală (ha): | H3: =SUM(F5:F204)
A4: Nr. | B4: Nume complet | C4: Telefon | D4: Localitate | E4: Județ | F4: Suprafață fermă (ha) | G4: Tractor(e) deținute | H4: Utilaje cumpărate de la Agro Salso | I4: Data ultimei achiziții | J4: Ultimul contact | K4: Potențial upsell | L4: Ce ar putea cumpăra | M4: Recomandat de cineva? | N4: Note
B5: Gheorghe Moldovan | C5: 07XX XXX XXX | D5: Salonta | E5: Bihor | F5: 45 | G5: UTB 650 + Landini 85 CP | H5: Grapă Mamut 2.5 | I5: 2024-03 | J5: 2025-11 | K5: Da | L5: Cultivator sau semănătoare | M5: Nu | N5: Client fidel, 3 ani. Vecinul Ion caută grapă.
A6: =IF(B6<>"", ROW()-4, "")
A7: =IF(B7<>"", ROW()-4, "")
A8: =IF(B8<>"", ROW()-4, "")
A9: =IF(B9<>"", ROW()-4, "")
A10: =IF(B10<>"", ROW()-4, "")
A11: =IF(B11<>"", ROW()-4, "")
A12: =IF(B12<>"", ROW()-4, "")
A13: =IF(B13<>"", ROW()-4, "")
A14: =IF(B14<>"", ROW()-4, "")
A15: =IF(B15<>"", ROW()-4, "")
A16: =IF(B16<>"", ROW()-4, "")
A17: =IF(B17<>"", ROW()-4, "")
... A204: =IF(B204<>"", ROW()-4, "")

Sheet LEAD-URI NOI
A1: AGRO SALSO — LEAD-URI NOI (din reclame, referral, telefon, vizite)
A2: ⚡ REGULĂ: Lead NOU = sună în maxim 2 ORE. Lead AFIR = sună în maxim 1 ORĂ.
A3: Total lead-uri: | B3: =COUNTA(E5:E504) | C3: Noi (nesunate): | D3: =COUNTIF(N5:N504,"Nou") | E3: Calificați: | F3: =COUNTIF(Q5:Q504,"Calificat") | G3: Vânduți: | H3: =COUNTIF(N5:N504,"Vândut") | I3: Pierduți: | J3: =COUNTIF(N5:N504,"Pierdut") | K3: Rată conversie: | L3: =IFERROR(COUNTIF(N5:N504,"Vândut")/COUNTA(E5:E504),0)
A4: Nr. | B4: Data lead | C4: Sursă | D4: Campanie / Detalii sursă | E4: Nume | F4: Telefon | G4: Localitate | H4: Județ | I4: Suprafață fermă (ha) | J4: Tractor deținut | K4: Produs interesat | L4: Model interesat | M4: Interes AFIR | N4: STATUS | O4: Data ultimului contact | P4: Următorul follow-up | Q4: Calitate lead | R4: Motiv pierdere (dacă pierdut) | S4: Note
A5: =IF(E5<>"", ROW()-4, "")
A6: =IF(E6<>"", ROW()-4, "")
A7: =IF(E7<>"", ROW()-4, "")
A8: =IF(E8<>"", ROW()-4, "")
A9: =IF(E9<>"", ROW()-4, "")
A10: =IF(E10<>"", ROW()-4, "")
A11: =IF(E11<>"", ROW()-4, "")
A12: =IF(E12<>"", ROW()-4, "")
A13: =IF(E13<>"", ROW()-4, "")
A14: =IF(E14<>"", ROW()-4, "")
A15: =IF(E15<>"", ROW()-4, "")
A16: =IF(E16<>"", ROW()-4, "")
... A504: =IF(E504<>"", ROW()-4, "")

Sheet PIPELINE AFIR
A1: AGRO SALSO — PIPELINE AFIR (DR-14 și alte sesiuni)
A2: Fiecare lead AFIR = potențială vânzare de ZECI DE MII de RON. Prioritate MAXIMĂ.
A3: Total proiecte AFIR: | B3: =COUNTA(B5:B104) | D3: Valoare totală pipeline: | E3: =SUM(J5:J104) | G3: Oferte trimise: | H3: =COUNTIF(K5:K104,"Da") | I3: Aprobate: | J3: =COUNTIF(O5:O104,"Aprobat")
A4: Nr. | B4: Fermier | C4: Telefon | D4: Localitate | E4: Suprafață (ha) | F4: Consultant AFIR | G4: Tel. consultant | H4: Utilaje solicitate în proiect | I4: Model(e) Dexwal | J4: Valoare estimată (RON) | K4: Ofertă conformă trimisă | L4: Data ofertă | M4: Factură proformă | N4: Fișă tehnică trimisă | O4: Status proiect AFIR | P4: Următorul pas | Q4: Note
A5: =IF(B5<>"", ROW()-4, "")
A6: =IF(B6<>"", ROW()-4, "")
A7: =IF(B7<>"", ROW()-4, "")
A8: =IF(B8<>"", ROW()-4, "")
A9: =IF(B9<>"", ROW()-4, "")
A10: =IF(B10<>"", ROW()-4, "")
A11: =IF(B11<>"", ROW()-4, "")
A12: =IF(B12<>"", ROW()-4, "")
A13: =IF(B13<>"", ROW()-4, "")
A14: =IF(B14<>"", ROW()-4, "")
A15: =IF(B15<>"", ROW()-4, "")
A16: =IF(B16<>"", ROW()-4, "")
... A104: =IF(B104<>"", ROW()-4, "")

Sheet FOLLOW-UP ZILNIC
A1: AGRO SALSO — FOLLOW-UP ZILNIC
A2: Dimineața la 07:00 — deschide acest tab și sună pe fiecare. Seara — completează rezultatul și adaugă apelurile de mâine.
A3: Apeluri azi: | B3: =COUNTIF(A5:A304,TODAY()) | C3: Făcute azi: | D3: =COUNTIFS(A5:A304,TODAY(),J5:J304,"Da") | E3: Rămase azi: | F3: =COUNTIFS(A5:A304,TODAY(),J5:J304,"Nu") | G3: Urgente nefăcute: | H3: =COUNTIFS(G5:G304,"Urgentă",J5:J304,"Nu")
A4: Data | B4: Oră planificată | C4: Cine trebuie sunat | D4: Telefon | E4: Motiv apel | F4: Tip | G4: Prioritate | H4: Rezultat apel | I4: Următoarea acțiune | J4: Făcut

Sheet DASHBOARD LUNAR
A1: AGRO SALSO — DASHBOARD & RAPORT LUNAR
A2: Completează o dată pe lună. Numerele se calculează automat din tab-urile anterioare + bugetul introdus manual.
A4: PERFORMANȚĂ LUNARĂ
A5: Luna | B5: Lead-uri noi total | C5: Din Meta Ads | D5: Din Google Ads | E5: Din Referral | F5: Din Grupuri Facebook | G5: Din AFIR | H5: Lead-uri contactate | I5: Lead-uri calificate | J5: Vizite la sediu | K5: Oferte trimise | L5: Oferte AFIR trimise | M5: Vânzări închise | N5: Valoare vânzări (RON) | O5: Buget ads cheltuit (RON) | P5: Cost per lead (RON) | Q5: Cost per vânzare (RON)
A6: Februarie 2026 | P6: =IFERROR(O6/B6,"") | Q6: =IFERROR(O6/M6,"")
A7: Martie 2026 | P7: =IFERROR(O7/B7,"") | Q7: =IFERROR(O7/M7,"")
A8: Aprilie 2026 | P8: =IFERROR(O8/B8,"") | Q8: =IFERROR(O8/M8,"")
A9: Mai 2026 | P9: =IFERROR(O9/B9,"") | Q9: =IFERROR(O9/M9,"")
A10: Iunie 2026 | P10: =IFERROR(O10/B10,"") | Q10: =IFERROR(O10/M10,"")
A11: Iulie 2026 | P11: =IFERROR(O11/B11,"") | Q11: =IFERROR(O11/M11,"")
A12: August 2026 | P12: =IFERROR(O12/B12,"") | Q12: =IFERROR(O12/M12,"")
A13: Septembrie 2026 | P13: =IFERROR(O13/B13,"") | Q13: =IFERROR(O13/M13,"")
A14: Octombrie 2026 | P14: =IFERROR(O14/B14,"") | Q14: =IFERROR(O14/M14,"")
A15: Noiembrie 2026 | P15: =IFERROR(O15/B15,"") | Q15: =IFERROR(O15/M15,"")
A16: Decembrie 2026 | P16: =IFERROR(O16/B16,"") | Q16: =IFERROR(O16/M16,"")
A17: Ianuarie 2027 | P17: =IFERROR(O17/B17,"") | Q17: =IFERROR(O17/M17,"")
A18: TOTAL | B18: =SUM(B6:B17) | C18: =SUM(C6:C17) | D18: =SUM(D6:D17) | E18: =SUM(E6:E17) | F18: =SUM(F6:F17) | G18: =SUM(G6:G17) | H18: =SUM(H6:H17) | I18: =SUM(I6:I17) | ... O18: =SUM(O6:O17) | P18: =IFERROR(AVERAGE(P6:P17),"") | Q18: =IFERROR(AVERAGE(Q6:Q17),"")
A21: DASHBOARD LIVE (calculat automat din celelalte tab-uri)
A22: Clienți în baza de date: | B22: ='CLIENȚI EXISTENȚI'!B3
A23: Clienți cu potențial upsell: | B23: ='CLIENȚI EXISTENȚI'!E3
A24: Total lead-uri noi: | B24: ='LEAD-URI NOI'!B3
A25: Lead-uri nesunate (NOI): | B25: ='LEAD-URI NOI'!D3
A26: Lead-uri calificate: | B26: ='LEAD-URI NOI'!F3
A27: Vânzări din lead-uri: | B27: ='LEAD-URI NOI'!H3
A28: Rată conversie lead→vânzare: | B28: ='LEAD-URI NOI'!L3
A29: Proiecte AFIR în pipeline: | B29: ='PIPELINE AFIR'!B3
A30: Valoare pipeline AFIR: | B30: ='PIPELINE AFIR'!E3
A31: Oferte AFIR trimise: | B31: ='PIPELINE AFIR'!H3
A32: Proiecte AFIR aprobate: | B32: ='PIPELINE AFIR'!J3
A35: LEAD-URI PE SURSĂ (calculat automat)
A36: Sursă | B36: Nr. lead-uri | C36: % din total
A37: Meta Ads | B37: =COUNTIF('LEAD-URI NOI'!C5:C504,"Meta Ads") | C37: =IFERROR(B37/'LEAD-URI NOI'!B3,0)
A38: Google Ads | B38: =COUNTIF('LEAD-URI NOI'!C5:C504,"Google Ads") | C38: =IFERROR(B38/'LEAD-URI NOI'!B3,0)
A39: Referral | B39: =COUNTIF('LEAD-URI NOI'!C5:C504,"Referral") | C39: =IFERROR(B39/'LEAD-URI NOI'!B3,0)
A40: Telefon direct | B40: =COUNTIF('LEAD-URI NOI'!C5:C504,"Telefon direct") | C40: =IFERROR(B40/'LEAD-URI NOI'!B3,0)
A41: Grup Facebook | B41: =COUNTIF('LEAD-URI NOI'!C5:C504,"Grup Facebook") | C41: =IFERROR(B41/'LEAD-URI NOI'!B3,0)
A42: Marketplace | B42: =COUNTIF('LEAD-URI NOI'!C5:C504,"Marketplace") | C42: =IFERROR(B42/'LEAD-URI NOI'!B3,0)
A43: Vizită spontană | B43: =COUNTIF('LEAD-URI NOI'!C5:C504,"Vizită spontană") | C43: =IFERROR(B43/'LEAD-URI NOI'!B3,0)
A44: AFIR | B44: =COUNTIF('LEAD-URI NOI'!C5:C504,"AFIR") | C44: =IFERROR(B44/'LEAD-URI NOI'!B3,0)
A47: LEAD-URI PE STATUS (calculat automat)
...
